Workbook

Sheet c
A1: 44 | J1: MOTOR | N1: CORONA/DIFERENCIAL | R1: TRANSMISION/CAJA DE CAMBIOS | V1: CAJA TRANSFRENCIA
A2: COD | B2: MATRICULA | C2: MARCA | D2: PROPIETARIO | E2: KM/HR | F2: ACTUAL | G2: PERMISO CIRCULACION | H2: SOAP | I2: REV. TECNICA | J2: FECHA DE CAMBIO | K2: ULTIMO | L2: PROXIMO | M2: FALTAN | N2: FECHA DE CAMBIO | O2: ULTIMO | P2: PROXIMO | R2: FECHA DE CAMBIO | S2: ULTIMO | T2: PROXIMO | V2: FECHA DE CAMBIO | W2: ULTIMA MANT | X2: PROXIMO | AA2: RAZON
A3: C-01 | B3: DZXV32 | C3: HYUNDAI | D3: DESCONTINUADA | F3: {=IF(A3:A1001="", "", IF(E3:E1001="KM", IFERROR(VLOOKUP(A3:A1001, DATA_LIMPIA!A:C, 3, FALSE), 0), IFERROR(VLOOKUP(A3:A1001, DATA_LIMPIA!A:C, 2, FALSE), 0) ) )} | G3: 45747 | H3: 45747 | I3: 45808 | J3: 45335 | K3: 274000 | L3: =K3+10000 -> 284000 | M3: =+L3-F3 -> 284000 | N3: 45184 | O3: 253714 | P3: =O3+40000 -> 293714 | Q3: =+P3-F3 -> 293714 | R3: 45184 | S3: 253714 | T3: =S3+40000 -> 293714 | U3: =+T3-F3 -> 293714 | X3: =W3+40000 -> 40000 | Y3: =+X3-F3 -> 40000 | AA3: SI
A4: C-02 | B4: FBWJ 56 | C4: NISSAN | D4: MARCO PARADA | E4: KM | F4: 379583 | G4: XX | H4: XX | I4: XX | J4: 45259 | K4: 372000 | L4: =K4+10000 -> 382000 | M4: =+L4-F4 -> 2417 | N4: 45079 | O4: 362000 | P4: =O4+40000 -> 402000 | Q4: =+P4-F4 -> 22417 | R4: 45079 | S4: 362000 | T4: =S4+40000 -> 402000 | U4: =+T4-F4 -> 22417 | V4: 45079 | W4: 362000 | X4: =W4+40000 -> 402000 | Y4: =+X4-F4 -> 22417 | Z4: 4X4
A5: C-03 | B5: FSLK 53 | C5: NISSAN | D5: DESCONTINUADA | E5: KM | F5: 332383 | G5: 45900 | H5: 46112 | I5: 45838 | J5: 45695 | K5: 329498 | L5: =K5+10000 -> 339498 | M5: =+L5-F5 -> 7115 | N5: 45695 | O5: 329498 | P5: =O5+40000 -> 369498 | Q5: =+P5-F5 -> 37115 | R5: 45695 | S5: 329498 | T5: =S5+40000 -> 369498 | U5: =+T5-F5 -> 37115 | V5: 45695 | W5: 329498 | X5: =W5+40000 -> 369498 | Y5: =+X5-F5 -> 37115 | Z5: 4X4 | AA5: BAJA POR BAJA POR BAJA . . . .. .. . . .
A6: C-04 | B6: GBPH 77 | C6: JAC | D6: HARCHAMAQ | E6: KM | F6: 386791 | G6: 46112 | H6: 46112 | I6: 46257 | J6: 46036 | K6: 384316 | L6: =K6+10000 -> 394316 | M6: =+L6-F6 -> 7525 | N6: 45861 | O6: 374027 | P6: =O6+40000 -> 414027 | Q6: =+P6-F6 -> 27236 | R6: 45861 | S6: 374027 | T6: =S6+40000 -> 414027 | U6: =+T6-F6 -> 27236 | X6: =W6+40000 -> 40000 | Y6: NO APLICA | Z6: 4X2
A7: C-06 | B7: GZZB73 | C7: MAHINDRA | D7: HARCHAMAQ | E7: KM | F7: 449279 | G7: 46112 | H7: 46112 | I7: 46174 | J7: 46084 | K7: 449209 | L7: =K7+10000 -> 459209 | M7: =+L7-F7 -> 9930 | N7: 45912 | O7: 426711 | P7: =O7+40000 -> 466711 | Q7: =+P7-F7 -> 17432 | R7: 45912 | S7: 426711 | T7: =S7+40000 -> 466711 | U7: =+T7-F7 -> 17432 | X7: =W7+40000 -> 40000 | Y7: NO APLICA | Z7: 4X2
A8: C-07 | B8: HYWS 35 | C8: SSANYONG | D8: DESCONTINUADA | J8: 45042 | K8: 270000 | L8: =K8+10000 -> 280000 | M8: =+L8-F8 -> 280000 | N8: 44897 | O8: 246725 | P8: =O8+40000 -> 286725 | Q8: =+P8-F8 -> 286725 | R8: 44897 | S8: 246725 | T8: =S8+40000 -> 286725 | U8: =+T8-F8 -> 286725 | X8: =W8+40000 -> 40000 | Y8: =+X8-F8 -> 40000
A9: C-08 | B9: HGSJ 62 | C9: MITSUBISHI | D9: DESCONTINUADA | J9: 45149 | K9: 270000 | L9: =K9+10000 -> 280000 | M9: =+L9-F9 -> 280000 | N9: 45149 | O9: 267115 | P9: =O9+40000 -> 307115 | Q9: =+P9-F9 -> 307115 | R9: 45149 | S9: 267115 | T9: =S9+40000 -> 307115 | U9: =+T9-F9 -> 307115 | V9: 45149 | W9: 267115 | X9: =W9+40000 -> 307115 | Y9: =+X9-F9 -> 307115
A10: C-09 | B10: JYFV 98 | C10: MITSUBISHI | D10: HARCHAMAQ | E10: KM | F10: 364846 | G10: 46112 | H10: 46112 | I10: 46327 | J10: 46071 | K10: 361779 | L10: =K10+10000 -> 371779 | M10: =+L10-F10 -> 6933 | N10: 45812 | O10: 329856 | P10: =O10+40000 -> 369856 | Q10: =+P10-F10 -> 5010 | R10: 45812 | S10: 329856 | T10: =S10+40000 -> 369856 | U10: =+T10-F10 -> 5010 | V10: 45203 | W10: 262655 | X10: =W10+40000 -> 302655 | Y10: NO APLICA | Z10: 4X2
A11: C-10 | B11: JZRK 51 | C11: MITSUBISHI | D11: DESCONTINUADA | J11: 45306 | K11: 300000 | L11: =K11+10000 -> 310000 | M11: =+L11-F11 -> 310000 | O11: 242000 | P11: =O11+40000 -> 282000 | Q11: =+P11-F11 -> 282000 | S11: 242000 | T11: =S11+40000 -> 282000 | U11: =+T11-F11 -> 282000 | X11: =W11+40000 -> 40000 | Y11: =+X11-F11 -> 40000
A12: C-11 | B12: BTVK72 | C12: FIAT | D12: DESCONTINUADA | F12: 390 | G12: 45900 | H12: 46112 | I12: 45808 | J12: 45176 | K12: 0 | L12: =K12+350 -> 350 | M12: =+L12-F12 -> -40 | P12: =O12+40000 -> 40000 | Q12: =+P12-F12 -> 39610 | T12: =S12+40000 -> 40000 | U12: =+T12-F12 -> 39610 | X12: =W12+40000 -> 40000 | Y12: NO APLICA | Z12: 4X2
A13: C-12 | B13: JZRK 53 | C13: MITSUBISHI | D13: HARCHAMAQ | E13: KM | F13: 362130 | G13: 46112 | H13: 46112 | I13: 46203 | J13: 45931 | K13: 359157 | L13: =K13+10000 -> 369157 | M13: =+L13-F13 -> 7027 | N13: 44978 | O13: 259780 | P13: =O13+40000 -> 299780 | Q13: =+P13-F13 -> -62350 | R13: 44978 | S13: 259780 | T13: =S13+40000 -> 299780 | U13: =+T13-F13 -> -62350 | X13: =W13+40000 -> 40000 | Y13: NO APLICA | Z13: 4X2
A14: C-13 | B14: KPGT 73 | C14: MITSUBISHI | D14: HARCHAMAQ | E14: KM | F14: 293489 | G14: 46112 | H14: 46112 | I14: 46203 | J14: 46002 | K14: 285143 | L14: =K14+10000 -> 295143 | M14: =+L14-F14 -> 1654 | N14: 45783 | O14: 262820 | P14: =O14+40000 -> 302820 | Q14: =+P14-F14 -> 9331 | R14: 45783 | S14: 262820 | T14: =S14+40000 -> 302820 | U14: =+T14-F14 -> 9331 | X14: =W14+40000 -> 40000 | Y14: NO APLICA | Z14: 4X2
A15: C-14 | B15: KPGT71 | C15: MITSUBISHI | D15: HARCHAMAQ | E15: KM | F15: 277993 | G15: 46112 | H15: 46112 | I15: 46113 | J15: 45968 | K15: 269000 | L15: =K15+10000 -> 279000 | M15: =+L15-F15 -> 1007 | N15: 45839 | O15: 264563 | P15: =O15+40000 -> 304563 | Q15: =+P15-F15 -> 26570 | R15: 45839 | S15: 264563 | T15: =S15+40000 -> 304563 | U15: =+T15-F15 -> 26570 | X15: =W15+40000 -> 40000 | Y15: NO APLICA | Z15: 4X2
A16: C-15 | B16: KPGT 72 | C16: MITSUBISHI | D16: HARCHAMAQ | E16: KM | F16: 373946 | G16: 46112 | H16: 46112 | I16: 46173 | J16: 45902 | K16: 371827 | L16: =K16+10000 -> 381827 | M16: =+L16-F16 -> 7881 | N16: 45719 | O16: 361535 | P16: =O16+40000 -> 401535 | Q16: =+P16-F16 -> 27589 | R16: 45719 | S16: 361535 | T16: =S16+40000 -> 401535 | U16: =+T16-F16 -> 27589 | V16: 45719 | W16: 361535 | X16: =W16+40000 -> 401535 | Y16: NO APLICA | Z16: 4X2
A17: C-16 | B17: KPGT 70 | C17: MITSUBISHI | D17: HARCHAMAQ | E17: KM | F17: 379492 | G17: 46112 | H17: 46112 | I17: 46419 | J17: 46051 | K17: 376726 | L17: =K17+10000 -> 386726 | M17: =+L17-F17 -> 7234 | N17: 45716 | O17: 354990 | P17: =O17+40000 -> 394990 | Q17: =+P17-F17 -> 15498 | R17: 45134 | S17: 281992 | T17: =S17+40000 -> 321992 | U17: =+T17-F17 -> -57500 | X17: =W17+40000 -> 40000 | Y17: NO APLICA | Z17: 4X2
A18: C-17 | B18: KPGT 74 | C18: MITSUBISHI | D18: HARCHAMAQ | E18: KM | F18: 251720 | G18: 46112 | H18: 46112 | I18: 46204 | J18: 46001 | K18: 247429 | L18: =K18+10000 -> 257429 | M18: =+L18-F18 -> 5709 | N18: 45161 | O18: 219000 | P18: =O18+40000 -> 259000 | Q18: =+P18-F18 -> 7280 | R18: 45161 | S18: 219000 | T18: =S18+40000 -> 259000 | U18: =+T18-F18 -> 7280 | V18: 45530 | W18: 219000 | X18: =W18+40000 -> 259000 | Y18: NO APLICA | Z18: 4X2
A19: C-18 | B19: KSRB30 | C19: MITSUBISHI | D19: HARCHAMAQ | E19: KM | F19: 352840 | G19: 46112 | H19: 46112 | I19: 46054 | J19: 46036 | K19: 347960 | L19: =K19+10000 -> 357960 | M19: =+L19-F19 -> 5120 | N19: 45768 | O19: 313700 | P19: =O19+40000 -> 353700 | Q19: =+P19-F19 -> 860 | R19: 45768 | S19: 313700 | T19: =S19+40000 -> 353700 | U19: =+T19-F19 -> 860 | V19: 45768 | W19: 313700 | X19: =W19+40000 -> 353700 | Y19: =+X19-F19 -> 860 | Z19: 4X4
A20: C-19 | B20: RCZX21 | C20: MITSUBISHI | D20: HARCHAMAQ | E20: KM | F20: 198675 | G20: 46112 | H20: 46112 | I20: 46142 | J20: 46028 | K20: 190158 | L20: =K20+10000 -> 200158 | M20: =+L20-F20 -> 1483 | N20: 45679 | O20: 151014 | P20: =O20+40000 -> 191014 | Q20: =+P20-F20 -> -7661 | R20: 45679 | S20: 151014 | T20: =S20+40000 -> 191014 | U20: =+T20-F20 -> -7661 | V20: 45679 | W20: 151014 | X20: =W20+40000 -> 191014 | Y20: =+X20-F20 -> -7661 | Z20: 4X4
A21: C-20 | B21: RCZX23 | C21: MITSUBISHI | D21: HARCHAMAQ | E21: KM | F21: 157411 | G21: 46112 | H21: 46112 | I21: 46203 | J21: 45981 | K21: 149813 | L21: =K21+10000 -> 159813 | M21: =+L21-F21 -> 2402 | N21: 45768 | O21: 134899 | P21: =O21+40000 -> 174899 | Q21: =+P21-F21 -> 17488 | R21: 45768 | S21: 134899 | T21: =S21+40000 -> 174899 | U21: =+T21-F21 -> 17488 | X21: =W21+40000 -> 40000 | Y21: NO APLICA | Z21: 4X2
A22: C-21 | B22: RCZX26 | C22: MITSUBISHI | D22: HARCHAMAQ | E22: KM | F22: 83380 | G22: 46112 | H22: 46112 | I22: 46266 | J22: 46073 | K22: 83099 | L22: =K22+10000 -> 93099 | M22: =+L22-F22 -> 9719 | N22: 46073 | O22: 83099 | P22: =O22+40000 -> 123099 | Q22: =+P22-F22 -> 39719 | R22: 46073 | S22: 83099 | T22: =S22+40000 -> 123099 | U22: =+T22-F22 -> 39719 | X22: =W22+40000 -> 40000 | Y22: NO APLICA | Z22: 4X2
A23: C-22 | B23: RCZX28 | C23: MITSUBISHI | D23: ITAU | E23: KM | F23: 192377 | G23: 46112 | H23: 46112 | I23: 46327 | J23: 46035 | K23: 184025 | L23: =K23+10000 -> 194025 | M23: =+L23-F23 -> 1648 | N23: 45805 | O23: 149517 | P23: =O23+40000 -> 189517 | Q23: =+P23-F23 -> -2860 | R23: 45805 | S23: 149517 | T23: =S23+40000 -> 189517 | U23: =+T23-F23 -> -2860 | X23: =W23+40000 -> 40000 | Y23: NO APLICA | Z23: 4X2
A24: C-23 | B24: RCWX81 | C24: MAXUS | D24: HARCHAMAQ | E24: KM | F24: 176598 | G24: 46112 | H24: 46112 | I24: 46113 | J24: 45995 | K24: 166307 | L24: =K24+10000 -> 176307 | M24: =+L24-F24 -> -291 | N24: 45533 | O24: 133144 | P24: =O24+40000 -> 173144 | Q24: =+P24-F24 -> -3454 | R24: 45533 | S24: 133144 | T24: =S24+40000 -> 173144 | U24: =+T24-F24 -> -3454 | V24: 45533 | W24: 133144 | X24: =W24+40000 -> 173144 | Y24: =+X24-F24 -> -3454 | Z24: 4X4
A25: C-24 | B25: RCXB16 | C25: MAXUS | D25: HARCHAMAQ | E25: KM | F25: 132877 | G25: 46112 | H25: 46112 | I25: 46266 | J25: 46036 | K25: 122932 | L25: =K25+10000 -> 132932 | M25: =+L25-F25 -> 55 | N25: 45146 | O25: 83892 | P25: =O25+40000 -> 123892 | Q25: =+P25-F25 -> -8985 | R25: 45146 | S25: 83892 | T25: =S25+40000 -> 123892 | U25: =+T25-F25 -> -8985 | V25: 45146 | W25: 83892 | X25: =W25+40000 -> 123892 | Y25: =+X25-F25 -> -8985 | Z25: 4X4
A26: C-25 | B26: RHDY49 | C26: MAXUS | D26: HARCHAMAQ | E26: KM | F26: 181399 | G26: 46112 | H26: 46112 | I26: 46388 | J26: 45997 | K26: 177228 | L26: =K26+10000 -> 187228 | M26: =+L26-F26 -> 5829 | N26: 45769 | O26: 154024 | P26: =O26+40000 -> 194024 | Q26: =+P26-F26 -> 12625 | R26: 45769 | S26: 154024 | T26: =S26+40000 -> 194024 | U26: =+T26-F26 -> 12625 | V26: 45769 | W26: 154024 | X26: =W26+40000 -> 194024 | Y26: =+X26-F26 -> 12625 | Z26: 4X4
A27: C-26 | B27: RTXW68 | C27: GREAT WALL | D27: ITAU | E27: KM | F27: 110338 | G27: 46112 | H27: 46112 | I27: 46327 | J27: 45989 | K27: 101747 | L27: =K27+10000 -> 111747 | M27: =+L27-F27 -> 1409 | N27: 45293 | O27: 21800 | P27: =O27+40000 -> 61800 | Q27: =+P27-F27 -> -48538 | R27: 45293 | S27: 21800 | T27: =S27+40000 -> 61800 | U27: =+T27-F27 -> -48538 | V27: 45293 | W27: 21800 | X27: =W27+40000 -> 61800 | Y27: =+X27-F27 -> -48538 | Z27: 4X4
A28: C-27 | B28: RTXW59 | C28: GREAT WALL | D28: ITAU | E28: KM | F28: 104845 | G28: 45900 | H28: 46112 | I28: 46388 | J28: 45869 | K28: 98939 | L28: =K28+10000 -> 108939 | M28: =+L28-F28 -> 4094 | N28: 45869 | O28: 98939 | P28: =O28+40000 -> 138939 | Q28: =+P28-F28 -> 34094 | R28: 45869 | S28: 98939 | T28: =S28+40000 -> 138939 | U28: =+T28-F28 -> 34094 | V28: 44936 | W28: 42258 | X28: =W28+40000 -> 82258 | Y28: =+X28-F28 -> -22587 | Z28: 4X4
A29: C-29 | B29: RWRH49 | C29: JMC | D29: ITAU | E29: KM | F29: 169061 | G29: 46112 | H29: 46112 | I29: 46388 | J29: 46037 | K29: 162799 | L29: =K29+10000 -> 172799 | M29: =+L29-F29 -> 3738 | N29: 45427 | O29: 130000 | P29: =O29+40000 -> 170000 | Q29: =+P29-F29 -> 939 | R29: 46037 | S29: 162799 | T29: =S29+40000 -> 202799 | U29: =+T29-F29 -> 33738 | V29: 45427 | W29: 130000 | X29: =W29+40000 -> 170000 | Y29: =+X29-F29 -> 939 | Z29: 4X4
A30: C-30 | B30: RWRH50 | C30: JMC | D30: ITAU | E30: HR | F30: 1507 | G30: 46112 | H30: 46112 | I30: 46419 | J30: 46085 | K30: 1441 | L30: =K30+350 -> 1791 | M30: =+L30-F30 -> 284 | N30: 45183 | O30: 0 | P30: =O30+2000 -> 2000 | Q30: =+P30-F30 -> 493 | R30: 53219 | S30: 0 | T30: =S30+2000 -> 2000 | U30: =+T30-F30 -> 493 | V30: 45183 | W30: 0 | X30: =W30+2000 -> 2000 | Y30: =+X30-F30 -> 493 | Z30: 4X4
A31: C-31 | B31: GLLL 86 | C31: DODGE | D31: HARCHAMAQ | E31: KM | F31: 169400 | G31: 46112 | H31: 46112 | I31: 46295 | J31: 45972 | K31: 165808 | L31: =K31+10000 -> 175808 | M31: =+L31-F31 -> 6408 | O31: 50000 | P31: =O31+40000 -> 90000 | Q31: =+P31-F31 -> -79400 | R31: 45016 | S31: 132500 | T31: =S31+40000 -> 172500 | U31: =+T31-F31 -> 3100 | V31: 45016 | W31: 132500 | X31: =W31+40000 -> 172500 | Y31: =+X31-F31 -> 3100 | Z31: 4X4
A32: c-33 | B32: RXRK45 | C32: JMC | D32: DESCONTINUADA | F32: 612 | AA32: camineta camineta
A33: C-34 | B33: HJCF 11 | C33: MAHINDRA | D33: DESCONTINUADA | K33: 280000 | L33: =K33+10000 -> 290000 | M33: =+L33-F33 -> 290000 | N33: 44953 | O33: 266467 | P33: =O33+40000 -> 306467 | Q33: =+P33-F33 -> 306467 | R33: 44953 | S33: 266467 | T33: =S33+40000 -> 306467 | U33: =+T33-F33 -> 306467 | X33: =W33+40000 -> 40000 | Y33: =+X33-F33 -> 40000
A34: C-35 | B34: SCSL76 | C34: JMC | D34: ITAU | E34: KM | F34: 46067 | G34: 46112 | H34: 46112 | I34: 46266 | J34: 45719 | K34: 40145 | L34: =K34+10000 -> 50145 | M34: =+L34-F34 -> 4078 | N34: 45084 | O34: 31114 | P34: =O34+40000 -> 71114 | Q34: =+P34-F34 -> 25047 | R34: 45084 | S34: 31114 | T34: =S34+40000 -> 71114 | U34: =+T34-F34 -> 25047 | V34: 45084 | W34: 31114 | X34: =W34+40000 -> 71114 | Y34: =+X34-F34 -> 25047 | Z34: 4X4
A35: C-36 | B35: GBPD93 | C35: ZNA | D35: JAIME HARCHA | E35: HR | F35: 541 | G35: 46112 | H35: 46112 | I35: 46203 | J35: 45944 | K35: 356 | L35: =K35+350 -> 706 | M35: =+L35-F35 -> 165 | N35: 44936 | O35: 183826 | P35: =O35+40000 -> 223826 | Q35: =+P35-F35 -> 223285 | R35: 44936 | S35: 183826 | T35: =S35+40000 -> 223826 | U35: =+T35-F35 -> 223285 | X35: =W35+40000 -> 40000 | Y35: NO APLICA | Z35: 4X2
A36: C-37 | B36: SLCT28 | C36: MAXUS | D36: SANTANDER | E36: KM | F36: 112046 | G36: 46112 | H36: 46112 | I36: 46692 | J36: 46063 | K36: 108992 | L36: =K36+10000 -> 118992 | M36: =+L36-F36 -> 6946 | N36: 45726 | O36: 74283 | P36: =O36+40000 -> 114283 | Q36: =+P36-F36 -> 2237 | R36: 45726 | S36: 74283 | T36: =S36+40000 -> 114283 | U36: =+T36-F36 -> 2237 | V36: 45726 | W36: 74283 | X36: =W36+40000 -> 114283 | Y36: =+X36-F36 -> 2237 | Z36: 4X4
A37: C-38 | B37: SRPL59 | C37: MAXUS | D37: SANTANDER | E37: KM | F37: 152250 | G37: 46112 | H37: 46112 | I37: 46753 | J37: 46085 | K37: 151276 | L37: =K37+10000 -> 161276 | M37: =+L37-F37 -> 9026 | N37: 46085 | O37: 151276 | P37: =O37+40000 -> 191276 | Q37: =+P37-F37 -> 39026 | R37: 45800 | S37: 110579 | T37: =S37+40000 -> 150579 | U37: =+T37-F37 -> -1671 | W37: 0 | X37: =W37+40000 -> 40000 | Y37: =+X37-F37 -> -112250 | Z37: 4X4
A38: C-39 | B38: SRPL60 | C38: MAXUS | D38: SANTANDER | E38: KM | F38: 87086 | G38: 46112 | H38: 46112 | I38: 46784 | J38: 46009 | K38: 77175 | L38: =K38+10000 -> 87175 | M38: =+L38-F38 -> 89 | N38: 45825 | O38: 55877 | P38: =O38+40000 -> 95877 | Q38: =+P38-F38 -> 8791 | R38: 45825 | S38: 55877 | T38: =S38+40000 -> 95877 | U38: =+T38-F38 -> 8791 | V38: 45825 | W38: 55877 | X38: =W38+40000 -> 95877 | Y38: =+X38-F38 -> 8791 | Z38: 4X4
A39: C-41 | B39: SDWX22 | C39: FORD | D39: DESCONTINUADA | E39: KM | F39: 103332 | G39: 46112 | H39: 46112 | I39: 46508 | J39: 45646 | K39: 102550 | L39: =K39+15000 -> 117550 | M39: =+L39-F39 -> 14218 | N39: 44896 | P39: =O39+40000 -> 40000 | Q39: =+P39-F39 -> -63332 | R39: 44896 | T39: =S39+40000 -> 40000 | U39: =+T39-F39 -> -63332 | X39: =W39+40000 -> 40000 | Y39: =+X39-F39 -> -63332 | Z39: 4X4
A40: C-42 | B40: SXVL55 | C40: DODGE RAM 1500 | D40: SANTANDER | E40: KM | F40: 40066 | G40: 46112 | H40: 46112 | I40: 46600 | J40: 45743 | K40: 40066 | L40: =K40+10000 -> 50066 | M40: =+L40-F40 -> 10000 | O40: 0 | P40: =O40+40000 -> 40000 | Q40: =+P40-F40 -> -66 | S40: 0 | T40: =S40+40000 -> 40000 | U40: =+T40-F40 -> -66 | W40: 0 | X40: =W40+40000 -> 40000 | Y40: =+X40-F40 -> -66 | Z40: 4X4
...

Sheet ca
A1: 52 | K1: 160 | L1: MOTOR | P1: CAJA DE CAMBIOS | T1: CORONA/DIFERENCIAL
A2: COD | B2: TIPO MAQUINARIA | C2: PATENTE | D2: MARCA | E2: PROPIETARIO | F2: KM/HR | G2: MODELO | H2: ACTUAL | I2: Permiso de circulacion | J2: REV.TECNICA | K2: SOAP | L2: FECHA CAMBIO | M2: ULTIMO | N2: PROXIMO | O2: FALTAN | P2: FECHA CAMBIO | Q2: ULTIMO | R2: PROXIMO | T2: FECHA CAMBIO | U2: ULTIMO | V2: PROXIMO | Y2: RAZON
A3: CA-01 | B3: CAMION ALJIBE | C3: KJ9233 | D3: MACK | E3: HARCHAMAQ | F3: HR | G3: DM690S | H3: {=IF(A3:A1000="", "", IF(F3:F1000="KM", IFERROR(VLOOKUP(A3:A1000, DATA_LIMPIA!A:C, 3, FALSE), 0), IFERROR(VLOOKUP(A3:A1000, DATA_LIMPIA!A:C, 2, FALSE), 0) ) )} -> 1807 | I3: 46295 | J3: 46123 | K3: 46295 | L3: 46043 | M3: 1614 | N3: =M3+350 -> 1964 | O3: =+N3-H3 -> 157 | P3: 46007 | Q3: 1553 | R3: =Q3+2000 -> 3553 | S3: =R3-H3 -> 1746 | T3: 46007 | U3: 1553 | V3: =U3+2000 -> 3553 | W3: =V3-H3 -> 1746
A4: CG-01 | B4: CAMION GANADERO | C4: YX4975 | D4: MITSUBISHI | E4: DESCONTINUADA | S4: =R4-H4 -> 0
A5: CG-02 | B5: CAMION GANADERO | C5: GGBJ29 | D5: FOTON | E5: HARCHAMAQ | F5: HR | H5: 112 | I5: 46295 | J5: 46271 | K5: 46295 | L5: 46043 | M5: 0 | N5: =M5+350 -> 350 | O5: =+N5-H5 -> 238 | P5: 46043 | Q5: 0 | R5: =Q5+2000 -> 2000 | S5: =R5-H5 -> 1888 | T5: 46043 | U5: 0 | V5: =U5+2000 -> 2000 | W5: =V5-H5 -> 1888
A6: CK-03 | B6: CHEVROLET | C6: TS2119 | D6: CHEVROLET | G6: KODIAK 241 | H6: 5173 | I6: 46295 | J6: 46126 | K6: 46295 | M6: 4823 | N6: =M6+350 -> 5173 | O6: =+N6-H6 -> 0 | S6: =R6-H6 -> -5173 | W6: =V6-H6 -> -5173
A7: CM-01 | B7: CAMION MIXER | C7: YZ6869 | D7: INTERNACIONAL | E7: HARCHAMAQ | F7: KM | G7: 7600 | H7: 372672 | I7: 46295 | J7: 46104 | K7: 46295 | L7: 45580 | M7: 366134 | N7: =M7+10000 -> 376134 | O7: =+N7-H7 -> 3462 | P7: 44835 | Q7: 352950 | R7: =Q7+40000 -> 392950 | S7: =R7-H7 -> 20278 | T7: 44835 | U7: 355390 | V7: =U7+40000 -> 395390 | W7: =V7-H7 -> 22718
A8: CP-01 | B8: CAMION 3/4 | C8: GKYL34 | D8: JMC | E8: DESCONTINUADA | G8: MOBILE WORSHOP TRUCK | L8: 44832 | M8: 318000 | N8: =M8+10000 -> 328000 | O8: =+N8-H8 -> 328000 | Q8: 273324 | R8: =Q8+2000 -> 275324 | S8: 0 | T8: =S8+2000 -> 2000 | U8: =T8+2000 -> 4000 | V8: =U8+2000 -> 6000 | W8: =V8+2000 -> 8000
A9: CP-02 | B9: CAMION 3/4 PLANO | C9: HKST11 | D9: FOTON | E9: HARCHAMAQ | F9: KM | G9: AUMARK 613 CS | H9: 317475 | I9: 46295 | J9: 46225 | K9: 46295 | L9: 45973 | M9: 309365 | N9: =M9+10000 -> 319365 | O9: =+N9-H9 -> 1890 | P9: 45174 | Q9: 285397 | R9: =Q9+40000 -> 325397 | S9: =R9-H9 -> 7922 | T9: 45174 | U9: 285397 | V9: =U9+40000 -> 325397 | W9: =V9-H9 -> 7922
A10: CP-03 | B10: CAMION 3/4 | C10: HKFG20 | D10: FOTON | E10: HARCHAMAQ | F10: KM | G10: AUMARK 613E | H10: 216887 | I10: 46295 | J10: 46106 | K10: 46295 | L10: 45994 | M10: 211902 | N10: =M10+10000 -> 221902 | O10: =+N10-H10 -> 5015 | Q10: 191817 | R10: =Q10+40000 -> 231817 | S10: =R10-H10 -> 14930 | U10: 191817 | V10: =U10+40000 -> 231817 | W10: =V10-H10 -> 14930
A11: CP-04 | B11: CAMION 3/4 PLANO | C11: LBLG59 | D11: MITSUBISHI | E11: HARCHAMAQ | F11: KM | G11: CANTER 7.5 | H11: 284014 | I11: 46295 | J11: 46110 | K11: 46295 | L11: 46069 | M11: 281592 | N11: =M11+10000 -> 291592 | O11: =+N11-H11 -> 7578 | P11: 46002 | Q11: 270518 | R11: =Q11+40000 -> 310518 | S11: =R11-H11 -> 26504 | T11: 45754 | U11: 248551 | V11: =U11+40000 -> 288551 | W11: =V11-H11 -> 4537
A12: CP-05 | B12: CAMION 3/4 PLANO | C12: RKYD89 | D12: MITSUBISHI FUSO | E12: HARCHAMAQ | F12: KM | G12: CANTER 815 | H12: 209398 | I12: 46295 | J12: 46267 | K12: 46295 | L12: 46057 | M12: 202073 | N12: =M12+10000 -> 212073 | O12: =+N12-H12 -> 2675 | P12: 45922 | Q12: 181962 | R12: =Q12+40000 -> 221962 | S12: =R12-H12 -> 12564 | T12: 45922 | U12: 181962 | V12: =U12+40000 -> 221962 | W12: =V12-H12 -> 12564
A13: CP-06 | B13: CAMION PLUMA | C13: DJBD80 | D13: SINOTRUCK | E13: HARCHAMAQ | F13: HR | G13: CG 190 | H13: 10104 | I13: 46295 | J13: 46189 | K13: 46295 | L13: 45980 | M13: 9952 | N13: =M13+350 -> 10302 | O13: =+N13-H13 -> 198 | P13: 45827 | Q13: 9578 | R13: =Q13+2000 -> 11578 | S13: =R13-H13 -> 1474 | T13: 45980 | U13: 9952 | V13: =U13+2000 -> 11952 | W13: =V13-H13 -> 1848
A14: CP-07 | B14: CAMION PLUMA | C14: DZYT67 | D14: FORD | E14: HARCHAMAQ | F14: KM | G14: CARGO 2429 | H14: 288056 | I14: 46295 | J14: 46225 | K14: 46295 | L14: 45929 | M14: 284574 | N14: =M14+10000 -> 294574 | O14: =+N14-H14 -> 6518 | P14: 45824 | Q14: 279482 | R14: =Q14+40000 -> 319482 | S14: =R14-H14 -> 31426 | T14: 45824 | U14: 279482 | V14: =U14+40000 -> 319482 | W14: =V14-H14 -> 31426
A15: CP-08 | B15: CAMION PLUMA | C15: SXBK30 | D15: IVECO | E15: BCI | F15: KM | G15: TECTOR | H15: 71432 | I15: 46295 | J15: 46258 | K15: 46295 | L15: 46027 | M15: 63244 | N15: =M15+10000 -> 73244 | O15: =+N15-H15 -> 1812 | P15: 45662 | Q15: 63244 | R15: =Q15+20000 -> 83244 | S15: =R15-H15 -> 11812 | T15: 46027 | U15: 63244 | V15: =U15+40000 -> 103244 | W15: =V15-H15 -> 31812
A16: CS-01 | B16: CAMION SLARRY | C16: GDRK79 | D16: MACK | E16: SALFA | F16: KM | G16: GU813 | H16: 98383 | I16: 46295 | J16: 46083 | K16: 46295 | M16: 98383 | N16: =M16+10000 -> 108383 | O16: =+N16-H16 -> 10000 | Q16: 98383 | R16: =Q16+20000 -> 118383 | S16: =R16-H16 -> 20000 | U16: 98383 | V16: =U16+20000 -> 118383 | W16: =V16-H16 -> 20000
A17: CT-01 | B17: CAMION TOLVA | C17: PH4334 | D17: FREIGHTLINER | E17: DESCONTINUADA | G17: FL 80 | H17: 0 | M17: 5430 | N17: 5680 | O17: =+N17-H17 -> 5680 | Q17: 4957 | R17: 5557 | S17: 0 | T17: 5557 | U17: 5557 | V17: 5557 | W17: 0
A18: CT-02 | B18: CAMION TOLVA | C18: NC-9007 | D18: INTERNACIONAL | E18: DESCONTINUADA | G18: F5070 | H18: 0 | M18: 5332 | N18: 5582 | O18: =+N18-H18 -> 5582 | S18: 0
A19: CT-03 | B19: CAMION TOLVA | C19: RD7433 | D19: MACK | E19: MELON | F19: HR | G19: DM 690 S | H19: 752 | I19: 45930 | J19: 45701 | K19: 45930 | L19: 45981 | M19: 433 | N19: =M19+350 -> 783 | O19: =+N19-H19 -> 31 | P19: 45531 | Q19: 50 | R19: =Q19+2000 -> 2050 | S19: =R19-H19 -> 1298 | T19: 45531 | U19: 50 | V19: =U19+2000 -> 2050 | W19: =V19-H19 -> 1298
A20: CT-04 | B20: CAMION TOLVA | C20: YD6671 | D20: IVECO | E20: DESCONTINUADA | G20: MPC410E38H | H20: 0 | L20: 44498 | M20: 8739 | N20: 8989 | O20: =+N20-H20 -> 8989 | Q20: 8739 | R20: 9339 | S20: =R20-H20 -> 9339 | U20: 8739 | V20: 9339 | W20: 0
A21: CT-05 | B21: CAMION TOLVA | C21: YD6674 | D21: IVECO | E21: DESCONTINUADA | G21: MPC410E38H | H21: 0 | M21: 0 | N21: 350 | O21: =+N21-H21 -> 350 | S21: =R21-H21 -> 0 | W21: =V21-H21 -> 0
A22: CT-06 | B22: CAMION TOLVA | C22: BSLY79 | D22: FREIGHTLINER | E22: HARCHAMAQ | F22: HR | G22: M2 106 | H22: 22191 | I22: 46295 | J22: 46125 | K22: 46295 | L22: 46054 | M22: 21976 | N22: =M22+350 -> 22326 | O22: =+N22-H22 -> 135 | P22: 45727 | Q22: 20609 | R22: =Q22+2000 -> 22609 | S22: =R22-H22 -> 418 | T22: 45727 | U22: 20609 | V22: =U22+2000 -> 22609 | W22: =V22-H22 -> 418
A23: CT-07 | B23: CAMION TOLVA | C23: CHPV26 | D23: FREIGHTLINER | E23: HARCHAMAQ | F23: HR | G23: M2 112 | H23: 19673 | I23: 46295 | J23: 46123 | K23: 46295 | L23: 46053 | M23: 19643 | N23: =M23+350 -> 19993 | O23: =+N23-H23 -> 320 | P23: 45845 | Q23: 18882 | R23: =Q23+2000 -> 20882 | S23: =R23-H23 -> 1209 | T23: 45845 | U23: 18882 | V23: =U23+2000 -> 20882 | W23: =V23-H23 -> 1209
A24: CT-08 | B24: CAMION TOLVA | C24: GVFS56 | D24: JAC | E24: HARCHAMAQ | G24: LANDER HFC 3311 | H24: 6537 | I24: 45930 | J24: 45783 | K24: 46295 | L24: 45497 | M24: 6131 | N24: =M24+350 -> 6481 | O24: =N24-H24 -> -56 | P24: 45497 | Q24: 6131 | R24: =Q24+2000 -> 8131 | S24: =R24-H24 -> 1594 | T24: 45497 | U24: 6131 | V24: =U24+2000 -> 8131 | W24: =V24-H24 -> 1594
A25: CT-09 | B25: CAMION TOLVA | C25: GGFY95 | D25: JAC | E25: DESCONTINUADA | F25: HR | G25: LANDER HFC 3311 | H25: 3590 | I25: 46295 | J25: 46038 | K25: 46295 | L25: 45976 | M25: 3444 | N25: =M25+350 -> 3794 | O25: =+N25-H25 -> 204 | P25: 45547 | Q25: 2239 | R25: =Q25+2000 -> 4239 | S25: =R25-H25 -> 649 | T25: 45547 | U25: 2239 | V25: =U25+2000 -> 4239 | W25: =V25-H25 -> 649
A26: CT-10 | B26: CAMION TOLVA | C26: HKDX21 | D26: FOTON | E26: HARCHAMAQ | F26: HR | G26: AUMAN 3239 | H26: 5326 | I26: 46295 | J26: 46188 | K26: 46295 | L26: 46022 | M26: 5059 | N26: =M26+350 -> 5409 | O26: =+N26-H26 -> 83 | P26: 45987 | Q26: 4914 | R26: =Q26+2000 -> 6914 | S26: =R26-H26 -> 1588 | T26: 45527 | U26: 3595 | V26: =U26+2000 -> 5595 | W26: =V26-H26 -> 269
A27: CT-11 | B27: CAMION TOLVA | C27: HKDX24 | D27: FOTON | E27: DESCONTINUADA | G27: AUMAN 3239 | H27: 0 | N27: 350 | O27: =+N27-H27 -> 350 | S27: =R27-H27 -> 0
A28: CT-12 | B28: CAMION TOLVA | C28: PDSF74 | D28: IVECO | E28: HARCHAMAQ | F28: HR | G28: TRAKKER HI LAND AD 380T50 | H28: 10306 | I28: 46295 | J28: 46162 | K28: 46295 | L28: 46083 | M28: 10229 | N28: =M28+350 -> 10579 | O28: =+N28-H28 -> 273 | P28: 45849 | Q28: 9425 | R28: =Q28+2000 -> 11425 | S28: =R28-H28 -> 1119 | T28: 45754 | U28: 9025 | V28: =U28+2000 -> 11025 | W28: =V28-H28 -> 719
A29: CT-13 | B29: CAMION TOLVA | C29: PDSF75 | D29: IVECO | E29: HARCHAMAQ | F29: HR | G29: TRAKKER HI LAND AD 380T50 | H29: 5813 | I29: 46295 | J29: 46261 | K29: 46295 | L29: 10/13/2026 | M29: 5787 | N29: =M29+350 -> 6137 | O29: =+N29-H29 -> 324 | P29: 45965 | Q29: 5058 | R29: =Q29+2000 -> 7058 | S29: =R29-H29 -> 1245 | T29: 45965 | U29: 5058 | V29: =U29+2000 -> 7058 | W29: =V29-H29 -> 1245
A30: CT-14 | B30: CAMION TOLVA | C30: RCKP70 | D30: MERCEDES BENZ | E30: HARCHAMAQ | F30: HR | G30: AROCS 3342 | H30: 11827 | I30: 46295 | J30: 46245 | K30: 46295 | L30: 46040 | M30: 11718 | N30: =M30+350 -> 12068 | O30: =+N30-H30 -> 241 | P30: 45768 | Q30: 9551 | R30: =Q30+2000 -> 11551 | S30: =R30-H30 -> -276 | T30: 45768 | U30: 9551 | V30: =U30+2000 -> 11551 | W30: =V30-H30 -> -276
A31: CT-15 | B31: CAMION TOLVA | C31: RCKP71 | D31: MERCEDES BENZ | E31: HARCHAMAQ | F31: HR | G31: AROCS 3342 | H31: 11540 | I31: 46295 | J31: 46153 | K31: 46295 | L31: 46041 | M31: 11091 | N31: =M31+350 -> 11441 | O31: =+N31-H31 -> -99 | P31: 45750 | Q31: 9382 | R31: =Q31+2000 -> 11382 | S31: =R31-H31 -> -158 | T31: 45750 | U31: 9382 | V31: =U31+2000 -> 11382 | W31: =V31-H31 -> -158
A32: CT-16 | B32: CAMION TOLVA | C32: RCKP72 | D32: MERCEDES BENZ | E32: HARCHAMAQ | F32: HR | G32: AROCS 3342 | H32: 99334 | I32: 46295 | J32: 46107 | K32: 46295 | L32: 46082 | M32: 99334 | N32: =M32+350 -> 99684 | O32: =+N32-H32 -> 350 | P32: 45988 | Q32: 10072 | R32: =Q32+2000 -> 12072 | S32: =R32-H32 -> -87262 | T32: 45988 | U32: 10072 | V32: =U32+2000 -> 12072 | W32: =V32-H32 -> -87262
A33: CT-17 | B33: CAMION TOLVA | C33: RCKP77 | D33: MERCEDES BENZ | E33: DESCONTINUADA | G33: AROCS 3342 | H33: 0 | J33: 45292 | L33: 45216 | M33: 5601 | N33: =M33+600 -> 6201 | O33: =+N33-H33 -> 6201 | P33: 45216 | Q33: =M33+0 -> 5601 | R33: =Q33+2000 -> 7601 | S33: =R33-H33 -> 7601 | T33: 45216 | U33: =M33+0 -> 5601 | V33: =U33+600 -> 6201 | W33: =V33-H33 -> 6201
A34: CT-18 | B34: CAMION TOLVA | C34: RCKP78 | D34: MERCEDES BENZ | E34: DESCONTINUADA | G34: AROCS 3342 | H34: 10924 | I34: 45930 | J34: 45924 | K34: 45930 | L34: 45839 | M34: 10795 | N34: =M34+350 -> 11145 | O34: =+N34-H34 -> 221 | P34: 45771 | Q34: 10476 | R34: =Q34+2000 -> 12476 | S34: =R34-H34 -> 1552 | T34: 45771 | U34: 10476 | V34: =U34+2000 -> 12476 | W34: =V34-H34 -> 1552
A35: CT-19 | B35: CAMION TOLVA | C35: RCKP79 | D35: MERCEDES BENZ | E35: DESCONTINUADA | G35: AROCS 3342 | H35: 0 | J35: 44856 | L35: 44924 | M35: 2590 | N35: =M35+600 -> 3190 | O35: =N35+600 -> 3790 | P35: =O35+600 -> 4390 | Q35: =P35+600 -> 4990 | R35: =Q35+600 -> 5590 | S35: =R35-H35 -> 5590 | T35: =S35+600 -> 6190 | U35: =T35+600 -> 6790 | V35: =U35+600 -> 7390 | W35: =V35+600 -> 7990
A36: CT-20 | B36: CAMION TOLVA | C36: BFTP53 | D36: MERCEDES BENZ | E36: DESCONTINUADA | F36: HR | G36: 3336 | H36: 16 | I36: 46295 | J36: 46064 | K36: 46295 | L36: 46000 | M36: 8318 | N36: =M36+350 -> 8668 | O36: =+N36-H36 -> 8652 | P36: 46000 | Q36: 8318 | R36: =Q36+2000 -> 10318 | S36: =R36-H36 -> 10302 | T36: 46000 | U36: 8318 | V36: =U36+2000 -> 10318 | W36: =V36-H36 -> 10302
A37: CT-21 | B37: CAMION TOLVA | C37: BFTP65 | D37: MERCEDES BENZ | E37: DESCONTINUADA | F37: HR | G37: 3336 | H37: 5242 | I37: 46295 | J37: 46071 | K37: 46295 | L37: 45874 | M37: 5014 | N37: =M37+350 -> 5364 | O37: =+N37-H37 -> 122 | Q37: 3381 | R37: =Q37+2000 -> 5381 | S37: =R37-H37 -> 139 | U37: 3381 | V37: =U37+2000 -> 5381 | W37: =V37-H37 -> 139
A38: CT-22 | B38: CAMION TOLVA | C38: BFTP66 | D38: MERCEDES BENZ | E38: DESCONTINUADA | F38: HR | G38: 3336 K | H38: 9221 | I38: 46295 | J38: 46064 | K38: 46295 | L38: 45957 | M38: 8829 | N38: =M38+350 -> 9179 | O38: =+N38-H38 -> -42 | P38: 45805 | Q38: 8459 | R38: =Q38+2000 -> 10459 | S38: =R38-H38 -> 1238 | T38: 45805 | U38: 8459 | V38: =U38+2000 -> 10459 | W38: =V38-H38 -> 1238
A39: CT-23 | B39: CAMION TOLVA | C39: BSPZ51-K | D39: MACK | E39: HARCHAMAQ | F39: HR | G39: GU 813 | H39: 16303 | I39: 46295 | J39: 46166 | K39: 46295 | L39: 46014 | M39: 15971 | N39: =M39+350 -> 16321 | O39: =+N39-H39 -> 18 | P39: 45630 | Q39: 14254 | R39: =Q39+2000 -> 16254 | S39: =R39-H39 -> -49 | T39: 45706 | U39: 14254 | V39: =U39+2000 -> 16254 | W39: =V39-H39 -> -49
A40: CT-24 | B40: CAMION TOLVA | C40: BDYC87-K | D40: MACK | E40: HARCHAMAQ | F40: HR | G40: GU 813 | H40: 441 | I40: 46295 | J40: 46164 | K40: 46295 | L40: 45943 | M40: 69 | N40: =M40+350 -> 419 | O40: =+N40-H40 -> -22 | P40: 45615 | Q40: 499 | R40: =Q40+2000 -> 2499 | S40: =R40-H40 -> 2058 | T40: 45615 | U40: 499 | V40: =U40+2000 -> 2499 | W40: =V40-H40 -> 2058
...

Sheet carg
A1: 9 | I1: MOTOR | M1: TRANSMISION | Q1: HIDRAULICO | U1: DIFERENCIAL/CUBOS
A2: COD | B2: MAQUINARIA | C2: MARCA | D2: PROPIETARIO | E2: MODELO | F2: PATENTE | G2: KM/HR | H2: ACTUAL | I2: FECHA CAMBIO | J2: ULTIMO | K2: PROXIMO | L2: FALTAN | M2: FECHA CAMBIO | N2: ULTIMO | O2: PROXIMO | Q2: FECHA CAMBIO | R2: ULTIMO | S2: PROXIMO | U2: FECHA CAMBIO | V2: ULTIMO | W2: PROXIMO | Z2: RAZON
A3: CF-01 | B3: CARGADOR FRONTAL | C3: DAEWOO | D3: DESCONTINUADA | E3: MG400III | H3: {=IF(A3:A1000="", "", IF(G3:G1000="KM", IFERROR(VLOOKUP(A3:A1000, DATA_LIMPIA!A:C, 3, FALSE), ""), IFERROR(VLOOKUP(A3:A1000, DATA_LIMPIA!A:C, 2, FALSE), "") ) )} | T3: =S3-H3 -> 0
A4: CF-02 | B4: CARGADOR FRONTAL | C4: CHANGLIN | D4: DESCONTINUADA | E4: ZL50G | T4: =S4-H4 -> 0
A5: CF-03 | B5: CARGADOR FRONTAL | C5: NEW HOLLAND | D5: HARCHAMAQ | E5: MF W190B | F5: CKTG19 | G5: HR | H5: 11346 | I5: 46000 | J5: 11071 | K5: =J5+350 -> 11421 | L5: =K5-H5 -> 75 | M5: 45195 | N5: 10625 | O5: =N5+2000 -> 12625 | P5: =O5-H5 -> 1279 | Q5: 45804 | R5: 10898 | S5: =R5+2000 -> 12898 | T5: =S5-H5 -> 1552 | U5: 45587 | V5: 10066 | W5: =V5+1000 -> 11066 | X5: =W5-H5 -> -280
A6: CF-04 | B6: CARGADOR FRONTAL | C6: VOLVO | D6: HARCHAMAQ | E6: L150G | F6: DSLH27-4 | G6: HR | H6: 7466 | I6: 46039 | J6: 7113 | K6: =J6+350 -> 7463 | L6: =K6-H6 -> -3 | M6: 45951 | N6: 6645 | O6: =N6+700 -> 7345 | P6: =O6-H6 -> -121 | Q6: 45750 | R6: 5889 | S6: =R6+2000 -> 7889 | T6: =S6-H6 -> 423 | U6: 46039 | V6: 7113 | W6: =V6+1000 -> 8113 | X6: =W6-H6 -> 647
A7: CF-05 | B7: CARGADOR FRONTAL | C7: CLINTON | D7: HARCHAMAQ | E7: LW300F | F7: LZRC22 | G7: HR | H7: 6372 | I7: 46011 | J7: 6119 | K7: =J7+350 -> 6469 | L7: =K7-H7 -> 97 | M7: 46011 | N7: 6119 | O7: =N7+2000 -> 8119 | P7: =O7-H7 -> 1747 | Q7: 46011 | R7: 6119 | S7: =R7+2000 -> 8119 | T7: =S7-H7 -> 1747 | U7: 45983 | V7: 5990 | W7: =V7+1000 -> 6990 | X7: =W7-H7 -> 618
A8: CF-06 | B8: CARGADOR FRONTAL | C8: JOHN DEERE | D8: BCI | E8: 624K-II | F8: PPFG75 | G8: HR | H8: 10723 | I8: 45953 | J8: 10254 | K8: =J8+350 -> 10604 | L8: =K8-H8 -> -119 | M8: 45953 | N8: 10249 | O8: =N8+2000 -> 12249 | P8: =O8-H8 -> 1526 | Q8: 45749 | R8: 9040 | S8: =R8+2000 -> 11040 | T8: =S8-H8 -> 317 | U8: 45750 | V8: 9062 | W8: =V8+1000 -> 10062 | X8: =W8-H8 -> -661
A9: CF-07 | B9: CARGADOR FRONTAL | C9: HYUNDAI | D9: HARCHAMAQ | E9: HL770 9S | F9: LFFZ69 | G9: HR | H9: 9130 | I9: 46073 | J9: 9057 | K9: =J9+350 -> 9407 | L9: =K9-H9 -> 277 | M9: 45910 | N9: 8255 | O9: =N9+2000 -> 10255 | P9: =O9-H9 -> 1125 | Q9: 45737 | R9: 7874 | S9: =R9+2000 -> 9874 | T9: =S9-H9 -> 744 | U9: 45910 | V9: 8255 | W9: =V9+1000 -> 9255 | X9: =W9-H9 -> 125
A10: CF-08 | B10: CARGADOR FRONTAL | C10: KOMATSU | D10: PAVIMENTOS QUILIN | F10: CYWH62 | G10: HR | H10: 23292 | I10: 45882 | J10: 23118 | K10: =J10+350 -> 23468 | L10: =K10-H10 -> 176 | M10: 45630 | N10: 22149 | O10: =N10+2000 -> 24149 | P10: =O10-H10 -> 857 | R10: 22085 | S10: =R10+2000 -> 24085 | T10: =S10-H10 -> 793 | U10: 45635 | V10: 22461 | W10: =V10+1000 -> 23461 | X10: =W10-H10 -> 169
A11: CF-09 | B11: CARGADOR FRONTAL | C11: KOMATSU | D11: PAVIMENTOS QUILIN | F11: DXGT18 | G11: HR | H11: 17265 | I11: 45972 | J11: 17253 | K11: =J11+350 -> 17603 | L11: =K11-H11 -> 338 | M11: 45567 | N11: 15889 | O11: =N11+2000 -> 17889 | P11: =O11-H5 -> 6543 | Q11: 45567 | R11: 15889 | S11: =R11+2000 -> 17889 | T11: =S11-H11 -> 624 | U11: 45567 | V11: 15889 | W11: =V11+1000 -> 16889 | X11: =W11-H6 -> 9423
A12: CF-10 | B12: CARGADOR FRONTAL | C12: KOMATSU | E12: AW470 | F12: PYCJ80 | G12: HR | H12: 4671 | J12: 4419 | K12: =J12+350 -> 4769 | L12: =K12-H12 -> 98 | N12: 4419 | O12: =N12+2000 -> 6419 | P12: =O12-H12 -> 1748 | R12: 4419 | S12: =R12+2000 -> 6419 | T12: =S12-H12 -> 1748 | V12: 4419 | W12: =V12+1000 -> 5419 | X12: =W12-H12 -> 748
A13: MC-01 | B13: MINI CARGADOR | C13: JOHN DEERE | E13: 250 | I13: 45418 | J13: 53040 | K13: =J13+350 -> 53390 | L13: =K13-H13 -> 53390 | P13: 0 | Q13: 45418 | R13: 53040 | S13: =R13+2000 -> 55040 | T13: 0 | X13: 0
A14: MC-02 | B14: MINI CARGADOR | C14: LUIGING | E14: A375 | F14: GXVV46-8 | K14: =J14+350 -> 350 | L14: =K14-H14 -> 350 | P14: 0 | T14: =S14-H14 -> 0 | X14: 0
A15: MC-03 | B15: MINI CARGADOR | C15: TOYOTA | G15: HR | H15: 18715 | I15: 46090 | J15: 18706 | K15: =J15+350 -> 19056 | L15: =K15-H15 -> 341 | T15: =S15-H15 -> -18715
A16: MC-04 | B16: MINI CARGADOR | C16: BOBCAT | G16: HR | H16: 7821 | I16: 46071 | J16: 7800 | K16: =J16+350 -> 8150 | L16: =K16-H16 -> 329 | M16: 45845 | N16: 7681 | O16: =J16+2000 -> 9800 | P16: =O16-H9 -> 670 | Q16: 45845 | R16: 7681 | S16: =J16+2000 -> 9800 | T16: =S16-H16 -> 1979 | X16: =W16-H5 -> -11346

Sheet retro
A1: 6 | L1: MOTOR | P1: TRAnSMISION | T1: HIDRAULICO | X1: CORONA/DIFERENCIAL
A2: COD | B2: MAQUINARIA | C2: MARCA | D2: MODELO | E2: PATENTE | F2: PROPIETARIO | G2: KM/HR | H2: ACTUAL | I2: Permiso de circulacion | J2: SOAP | K2: REV.TECNICA | L2: FECHA CAMBIO | M2: ULTIMO | N2: PROXIMO | O2: FALTAN | P2: FECHA CAMBIO | Q2: ULTIMO | R2: PROXIMO | T2: FECHA CAMBIO | U2: ULTIMO | V2: PROXIMO ACEITE | X2: FECHA CAMBIO | Y2: ULTIMO | Z2: PROXIMO ACEITE | AC2: RAZON
A3: RX-01 | B3: RETROEXCAVADORA | C3: JOHN DEERE | D3: 310J | E3: BGDW56-7 | F3: DESCONTINUADA | G3: HR | H3: {=IF(A3:A1000="", "", IF(G3:G1000="KM", IFERROR(VLOOKUP(A3:A1000, DATA_LIMPIA!A:C, 3, FALSE), "Sin Datos"), IFERROR(VLOOKUP(A3:A1000, DATA_LIMPIA!A:C, 2, FALSE), "Sin Datos") ) )} -> 21109 | I3: 45930 | J3: 45930 | K3: 45859 | L3: 44964 | M3: 20777 | N3: =M3+350 -> 21127 | O3: =N3-H3 -> 18 | Q3: 20465 | R3: =Q3+2000 -> 22465 | S3: =R3-H3 -> 1356 | U3: 20465 | V3: =U3+2000 -> 22465 | W3: =V3-H3 -> 1356 | Y3: 20465 | Z3: =Y3+2000 -> 22465 | AA3: =Z3-H3 -> 1356
A4: RX-02 | B4: RETROEXCAVADORA | C4: JOHN DEERE | D4: 310G | E4: BGDW56-7 | F4: HARCHAMAQ | G4: HR | H4: 711 | I4: 45930 | J4: 45930 | K4: 45859 | L4: 45922 | M4: 395 | N4: =M4+350 -> 745 | O4: =N4-H4 -> 34 | P4: 41738 | Q4: 8360 | R4: =Q4+2000 -> 10360 | S4: =R4-H4 -> 9649 | U4: 5680 | V4: =U4+2000 -> 7680 | W4: =V4-H4 -> 6969 | Y4: 5680 | Z4: =Y4+2000 -> 7680 | AA4: =Z4-H4 -> 6969
A5: RX-03 | B5: RETROEXCAVADORA | C5: JCB | D5: 3C | E5: FPLK20-K | F5: HARCHAMAQ | G5: HR | H5: 3503 | I5: 46295 | J5: 46295 | K5: 46372 | L5: 46048 | M5: 809 | N5: =M5+350 -> 1159 | O5: =N5-H5 -> -2344 | P5: 45468 | Q5: -613 | R5: =Q5+2000 -> 1387 | S5: =R5-H5 -> -2116 | T5: 45468 | U5: -613 | V5: =U5+2000 -> 1387 | W5: =V5-H5 -> -2116 | X5: 45468 | Y5: -613 | Z5: =Y5+2000 -> 1387 | AA5: =Z5-H5 -> -2116
A6: RX-04 | B6: RETROEXCAVADORA | C6: CATERPILLAR | D6: 416E | E6: GTJH71-2 | F6: HARCHAMAQ | G6: HR | H6: 16512 | I6: 46295 | J6: 46295 | K6: 47056 | L6: 46082 | M6: 16464 | N6: =M6+350 -> 16814 | O6: =N6-H6 -> 302 | P6: 45825 | Q6: 15255 | R6: =Q6+2000 -> 17255 | S6: =R6-H6 -> 743 | T6: 45593 | U6: 15006 | V6: =U6+2000 -> 17006 | W6: =V6-H6 -> 494 | X6: 45895 | Y6: 15255 | Z6: =Y6+2000 -> 17255 | AA6: =Z6-H6 -> 743
A7: RX-05 | B7: RETROEXCAVADORA | C7: NEW HOLLAND | D7: B90B | E7: GYXY37-3 | F7: HARCHAMAQ | G7: HR | H7: 5564 | I7: 46295 | J7: 46295 | K7: 47101 | L7: 45980 | M7: 5296 | N7: =M7+350 -> 5646 | O7: =N7-H7 -> 82 | P7: 45895 | Q7: 5155 | R7: =Q7+2000 -> 7155 | S7: =R7-H7 -> 1591 | T7: 45155 | U7: 2635 | V7: =U7+2000 -> 4635 | W7: =V7-H7 -> -929 | X7: 45895 | Y7: 5155 | Z7: =Y7+2000 -> 7155 | AA7: =Z7-H7 -> 1591
A8: RX-06 | B8: RETROEXCAVADORA | C8: NEW HOLLAND | D8: B90B | E8: GYXY36-5 | F8: HARCHAMAQ | G8: HR | H8: 707 | I8: 46295 | J8: 46295 | K8: 47408 | L8: 45772 | M8: 494 | N8: =M8+350 -> 844 | O8: =N8-H8 -> 137 | P8: 45895 | Q8: 399 | R8: =Q8+2000 -> 2399 | S8: =R8-H8 -> 1692 | T8: 45401 | U8: 9302 | V8: =U8+2000 -> 11302 | W8: =V8-H8 -> 10595 | X8: 45132 | Y8: 8598 | Z8: =Y8+2000 -> 10598 | AA8: =Z8-H8 -> 9891
A9: RX-07 | B9: RETROEXCAVADORA | C9: JCB | D9: 3CXG | E9: HYVX68-K | F9: JAIME HARCHA | G9: HR | H9: 13238 | I9: 45930 | J9: 45930 | K9: 47211 | L9: 45664 | M9: 12885 | N9: =M9+350 -> 13235 | O9: =N9-H9 -> -3 | P9: 45761 | Q9: 12142 | R9: =Q9+2000 -> 14142 | S9: =R9-H9 -> 904 | T9: 45761 | U9: 12142 | V9: =U9+2000 -> 14142 | W9: =V9-H9 -> 904 | X9: 45761 | Y9: 12142 | Z9: =Y9+2000 -> 14142 | AA9: =Z9-H9 -> 904
A10: RX-08 | B10: RETROEXCAVADORA | C10: JOHN DEERE | D10: 310P 4X4 | E10: TRSL.95-4 | F10: SANTANDER | G10: HR | H10: 11026 | I10: 46295 | J10: 46295 | K10: 47010 | L10: 46059 | M10: 2324 | N10: =M10+350 -> 2674 | O10: =N10-H10 -> -8352 | P10: 45996 | Q10: 1996 | R10: =Q10+2000 -> 3996 | S10: =R10-H10 -> -7030 | T10: 45996 | U10: 1996 | V10: =U10+2000 -> 3996 | W10: =V10-H10 -> -7030 | X10: 45996 | Y10: 1996 | Z10: =Y10+2000 -> 3996 | AA10: =Z10-H10 -> -7030
A11: RXm-09 | B11: RETROEXCAVADORA | C11: JOHN DEERE | E11: TRSL.99-7 | F11: SANTANDER | G11: HR | H11: 2768 | I11: 46295 | J11: 46295 | K11: 47010 | L11: 46090 | M11: 2743 | N11: =M11+350 -> 3093 | O11: =N11-H11 -> 325 | P11: 45939 | Q11: 1980 | R11: =Q11+2000 -> 3980 | S11: =R11-H11 -> 1212 | T11: 45939 | U11: 1980 | V11: =U11+2000 -> 3980 | W11: =V11-H11 -> 1212 | X11: 45939 | Y11: 1980 | Z11: =Y11+2000 -> 3980 | AA11: =Z11-H11 -> 1212

Sheet ex
A1: 19 | I1: MOTOR | M1: MANDO FINAL | Q1: HIDRAULICO
A2: COD | B2: MAQUINARIA | C2: MARCA | D2: MODELO | E2: PATENTE | F2: PROPIETARIO | G2: KM/HR | H2: ACTUAL | I2: FECHA CAMBIO | J2: ULTIMO | K2: PROXIMO | L2: FALTAN | M2: FECHA CAMBIO | N2: ULTIMO | O2: PROXIMO | Q2: FECHA CAMBIO | R2: ULTIMO | S2: PROXIMO | V2: RAZON
A3: EX-01 | B3: EXCAVADORA | C3: JOHN DEERE | D3: 790 | F3: DESCONTINUADA | H3: {=IF(A3:A1000="", "", IF(G3:G1000="KM", IFERROR(VLOOKUP(A3:A1000, DATA_LIMPIA!A:C, 3, FALSE), ""), IFERROR(VLOOKUP(A3:A1000, DATA_LIMPIA!A:C, 2, FALSE), "") ) )}
A4: EX-02 | B4: EXCAVADORA | C4: KOBELCO | D4: SK200LC4 | E4: ZX4320-0 | F4: DESCONTINUADA | G4: HR | H4: 1 | S4: =R4+2000 -> 2000
A5: EX-03 | B5: EXCAVADORA | C5: JCB | D5: JS200LC | G5: HR | H5: 8630 | I5: 45974 | J5: 8478 | K5: =J5+350 -> 8828 | L5: =K5-H5 -> 198 | M5: 45811 | N5: 8051 | O5: =N5+1000 -> 9051 | P5: =O5-H5 -> 421 | Q5: 45811 | R5: 8051 | S5: =R5+2000 -> 10051 | T5: =S5-H5 -> 1421
A6: EX-04 | B6: EXCAVADORA | C6: JCB | D6: JS200LC | E6: BGVW80-0 | F6: DESCONTINUADA | I6: 44792 | P6: =O6-H6 -> 0 | S6: =R6+2000 -> 2000 | T6: =S6+2000 -> 4000
A7: EX-05 | B7: EXCAVADORA | C7: JCB | D7: JS220LC | F7: DESCONTINUADA | I7: 45111 | J7: 7805 | K7: =J7+350 -> 8155 | L7: =K7+350 -> 8505 | M7: =L7+350 -> 8855 | N7: 7740 | O7: =N7+1000 -> 8740 | P7: =O7-H7 -> 8740 | Q7: 44592 | R7: 7740 | S7: =R7+2000 -> 9740 | T7: =S7+2000 -> 11740
A8: EX-06 | B8: EXCAVADORA | C8: JCB | D8: 330LC | E8: DRXC28 | F8: HARCHAMAQ | G8: HR | H8: 16210 | I8: 45966 | J8: 15944 | K8: =J8+350 -> 16294 | L8: =K8-H8 -> 84 | M8: 45490 | N8: 14352 | O8: =N8+1000 -> 15352 | P8: =O8-H8 -> -858 | Q8: 45966 | R8: 15944 | S8: =R8+2000 -> 17944 | T8: =S8-H8 -> 1734
A9: EX-07 | B9: EXCAVADORA | C9: KOMATSU | D9: PC200LC-8MO | E9: JRKH82-1 | F9: HARCHAMAQ | G9: HR | H9: 16274 | I9: 46051 | J9: 15960 | K9: =J9+350 -> 16310 | L9: =K9-H9 -> 36 | M9: 45878 | N9: 15116 | O9: =N9+1000 -> 16116 | P9: =O9-H9 -> -158 | Q9: 45758 | R9: 14641 | S9: =R9+2000 -> 16641 | T9: =S9-H9 -> 367
A10: EX-08 | B10: EXCAVADORA | C10: KOMATSU | D10: PC200LC-8MO | E10: JVXT34-7 | F10: ITAU | G10: HR | H10: 11023 | I10: 46065 | J10: 10807 | K10: =J10+350 -> 11157 | L10: =K10-H10 -> 134 | M10: 45748 | N10: 9912 | O10: =N10+1000 -> 10912 | P10: =O10-H10 -> -111 | Q10: 45748 | R10: 9912 | S10: =R10+2000 -> 11912 | T10: =S10-H10 -> 889
A11: EX-09 | B11: EXCAVADORA | C11: KOMATSU | D11: PC300LC-8 | E11: RHDP26 | G11: HR | H11: 11734 | I11: 46051 | J11: 11362 | K11: =J11+350 -> 11712 | L11: =K11-H11 -> -22 | M11: 45938 | N11: 10614 | O11: =N11+1000 -> 11614 | P11: =O11-H11 -> -120 | Q11: 45938 | R11: 10614 | S11: =R11+2000 -> 12614 | T11: =S11-H11 -> 880
A12: EX-10 | B12: EXCAVADORA | C12: KOMATSU | D12: PC300LC-8 | G12: HR | H12: 10229 | I12: 46094 | J12: 10208 | K12: =J12+350 -> 10558 | L12: =K12-H12 -> 329 | M12: 46041 | N12: 9775 | O12: =N12+1000 -> 10775 | P12: =O12-H12 -> 546 | Q12: 45548 | R12: 7613 | S12: =R12+2000 -> 9613 | T12: =S12-H12 -> -616
A13: EX-11 | B13: EXCAVADORA | C13: KOMATSU | D13: PC200LC-8MO | E13: KTRD37 | F13: HARCHAMAQ | G13: HR | H13: 11096 | I13: 46073 | J13: 10948 | K13: =J13+350 -> 11298 | L13: =K13-H13 -> 202 | M13: 46073 | N13: 10948 | O13: =N13+1000 -> 11948 | P13: =O13-H13 -> 852 | Q13: 46073 | R13: 10948 | S13: =R13+2000 -> 12948 | T13: =S13-H13 -> 1852
A14: EX-12 | B14: EXCAVADORA | C14: JOHN DEERE | D14: 350G | E14: JJLH67-6 | F14: BCI | G14: HR | H14: 10256 | I14: 45982 | J14: 9964 | K14: =J14+350 -> 10314 | L14: =K14-H14 -> 58 | M14: 45771 | N14: 9214 | O14: =N14+1000 -> 10214 | P14: =O14-H14 -> -42 | Q14: 45771 | R14: 9214 | S14: =R14+2000 -> 11214 | T14: =S14-H14 -> 958
A15: EX-13 | B15: EXCAVADORA | C15: KOMATSU | D15: PC300LC-8 | G15: HR | H15: 11376 | I15: 45456 | J15: 11231 | K15: =J15+350 -> 11581 | L15: =K15-H15 -> 205 | M15: 45306 | N15: 10352 | O15: =N15+1000 -> 11352 | P15: =O15-H15 -> -24 | Q15: 45306 | R15: 10352 | S15: =R15+2000 -> 12352 | T15: =S15-H15 -> 976
A16: EX-14 | B16: EXCAVADORA | C16: KOMATSU | D16: PC200LC-8MO | E16: KFZK38-5 | F16: KOMATSU | G16: HR | H16: 9932 | I16: 46094 | J16: 9914 | K16: =J16+350 -> 10264 | L16: =K16-H16 -> 332 | M16: 45955 | N16: 9171 | O16: =N16+1000 -> 10171 | P16: =O16-H16 -> 239 | Q16: 45665 | R16: 9543 | S16: =R16+2000 -> 11543 | T16: =S16-H16 -> 1611
A17: EX-15 | B17: EXCAVADORA | C17: KOMATSU | D17: PC210 LC | E17: THYP52 | G17: HR | H17: 3801 | I17: 45996 | J17: 3412 | K17: =J17+350 -> 3762 | L17: =K17-H17 -> -39 | M17: 45999 | N17: 3412 | O17: =N17+1000 -> 4412 | P17: =O17-H17 -> 611 | Q17: 45813 | R17: 2425 | S17: =R17+2000 -> 4425 | T17: =S17-H17 -> 624
A18: EX-16 | B18: EXCAVADORA | C18: KOMATSU | D18: PC300 | E18: SJTT92 | F18: KOMATSU | G18: HR | H18: 4242 | I18: 46053 | J18: 3893 | K18: =J18+350 -> 4243 | L18: =K18-H18 -> 1 | M18: 45856 | N18: 2503 | O18: =N18+1000 -> 3503 | P18: =O18-H18 -> -739 | Q18: 45797 | R18: 2161 | S18: =R18+2000 -> 4161 | T18: =S18-H18 -> -81
A19: EX-17 | B19: EXCAVADORA | C19: KOMATSU | D19: PC210 LC | E19: SDRZ54 | G19: HR | H19: 1191 | I19: 46078 | J19: 1080 | K19: =J19+250 -> 1330 | L19: =K19-H19 -> 139 | O19: =N19+1000 -> 1000 | P19: =O19-H19 -> -191 | S19: =R19+2000 -> 2000 | T19: =S19-H19 -> 809
A20: EX-18 | B20: EXCAVADORA | C20: KOMATSU | D20: PC210 LC | E20: VHTG61 | G20: HR | H20: 1036 | I20: 46094 | J20: 1019 | K20: =J20+250 -> 1269 | L20: =K20-H20 -> 233 | O20: =N20+1000 -> 1000 | P20: =O20-H20 -> -36 | S20: =R20+2000 -> 2000 | T20: =S20-H20 -> 964
A21: EX-19 | B21: EXCAVADORA | C21: KOMATSU | D21: PC210 LC | E21: VHTG55 | G21: HR | H21: 1041 | I21: 46093 | J21: 1022 | K21: =J21+250 -> 1272 | L21: =K21-H21 -> 231 | O21: =N21+1000 -> 1000 | P21: =O21-H21 -> -41 | S21: =R21+2000 -> 2000 | T21: =S21-H21 -> 959
A22: EX-20 | B22: EXCAVADORA | C22: KOMATSU | D22: PC290 LC | E22: VPTD92 | G22: HR | H22: 806 | I22: 46059 | J22: 547 | K22: =J22+250 -> 797 | L22: =K22-H22 -> -9 | O22: =N22+1000 -> 1000 | P22: =O22-H22 -> 194 | S22: =R22+2000 -> 2000 | T22: =S22-H22 -> 1194
A23: EX-21 | B23: EXCAVADORA | C23: JHON DEERE | D23: 350GL | E23: RYHV75 | G23: HR | H23: 5257 | I23: 46071 | J23: 5166 | K23: =J23+350 -> 5516 | L23: =K23-H23 -> 259 | O23: =N23+1000 -> 1000 | P23: =O23-H23 -> -4257 | S23: =R23+2000 -> 2000 | T23: =S23-H23 -> -3257
A24: MX-01 | B24: MINI EXCAVADORA | C24: CATERPILLAR | D24: 308B-CR | F24: DESCONTINUADA | I24: 45645 | J24: 9850 | K24: =J24+350 -> 10200 | L24: =K24+350 -> 10550 | M24: =L24+350 -> 10900 | N24: 6850 | O24: =N24+1000 -> 7850 | P24: =O24+1000 -> 8850 | R24: 6850 | S24: =R24+2000 -> 8850 | T24: =S24+2000 -> 10850
A25: MX-02 | B25: MINI EXCAVADORA | C25: WAKER | D25: NEUSON3503 | E25: HWFT99 | F25: ALCARRAZ | G25: HR | H25: 7306 | I25: 45968 | J25: 7236 | K25: =J25+350 -> 7586 | L25: =K25-H25 -> 280 | M25: 45250 | N25: 6591 | O25: =N25+1000 -> 7591 | P25: =O25-H25 -> 285 | Q25: 45446 | R25: 6796 | S25: =R25+2000 -> 8796 | T25: =S25-H25 -> 1490
A26: MX-03 | B26: MINI EXCAVADORA | C26: JCB | D26: 8035ZTS | E26: KHSJ.37-7 | F26: JAIME HARCHA | G26: HR | H26: 3426 | I26: 45593 | J26: 3368 | K26: =J26+350 -> 3718 | L26: =K26-H26 -> 292 | M26: 46031 | N26: 3426 | O26: =N26+1000 -> 4426 | P26: =O26-H26 -> 1000 | Q26: 46031 | R26: 3426 | S26: =R26+2000 -> 5426 | T26: =S26-H26 -> 2000

Sheet bull
A1: 4 | B1: 45824.737 | I1: MOTOR | M1: TRANSMISION | Q1: HIDRAULICO | U1: MANDO FINAL
A2: COD | B2: MAQUINARIA | C2: MARCA | D2: MODELO | E2: PATENTE | F2: PROPIETARIO | G2: KM/HR | H2: ACTUAL | I2: FECHA CAMBIO | J2: ULTIMO | K2: PROXIMO FILTROS | L2: FALTAN | M2: FECHA CAMBIO | N2: ULTIMO | O2: PROXIMO FILTROS | Q2: FECHA CAMBIO | R2: ULTIMO | S2: PROXIMO | U2: FECHA CAMBIO | V2: ULTIMO | W2: PROXIMO | Z2: RAZON
A3: BD-01 | B3: BULLDOZER | C3: JOHN DEERE | D3: 650G | F3: DESCONTINUADA | H3: {=IF(A3:A1000="", "", IF(G3:G1000="KM", IFERROR(VLOOKUP(A3:A1000, DATA_LIMPIA!A:C, 3, FALSE), "Sin Datos"), IFERROR(VLOOKUP(A3:A1000, DATA_LIMPIA!A:C, 2, FALSE), "Sin Datos") ) )} -> 1753 | I3: 45066 | J3: 1668 | K3: =J3+350 -> 2018 | L3: =K3-H3 -> 265 | N3: 10737 | P3: =O3-H3 -> -1753 | R3: 10737 | T3: =S3-H3 -> -1753 | V3: 10737 | X3: =W3-H3 -> -1753 | Z3: SI
A4: BD-02 | B4: BULLDOZER | C4: CATERPILLAR | D4: D6T | E4: CCKZ72 | F4: HARCHA MAQUINARIA | G4: HR | H4: 12396 | I4: 45400 | J4: 12132 | K4: =J4+350 -> 12482 | L4: =K4-H4 -> 86 | P4: =O4-H4 -> -12396 | T4: =S4-H4 -> -12396 | X4: =W4-H4 -> -12396
A5: BD-03 | B5: BULLDOZER | C5: JOHN DEERE | D5: 850G | E5: KSRG22-7 | F5: BCI | G5: HR | H5: 11740 | I5: 46007 | J5: 11361 | K5: =J5+350 -> 11711 | L5: =K5-H5 -> -29 | M5: 45817 | N5: 10600 | O5: =N5+2000 -> 12600 | P5: =O5-H5 -> 860 | Q5: 45817 | R5: 10600 | S5: =R5+2000 -> 12600 | T5: =S5-H5 -> 860 | U5: 45817 | V5: 10600 | W5: =V5+2000 -> 12600 | X5: =W5-H5 -> 860

Sheet tract
A1: 5 | M1: MOTOR | Q1: TRANSMISION | U1: HIDRAULICO | Y1: DIFERENCIAL
A2: COD | B2: MAQUINARIA | C2: MARCA | D2: MODELO | E2: PATENTE | F2: PROPIETARIO | G2: KM/HR | H2: HOROMETRO ACTUALlZADO | I2: PERMISO CIRCULACION | J2: SOAP | K2: REV. TECNICA | L2: FECHA CAMBIO | M2: ULTIMO | N2: PROXIMO | O2: FALTAN | P2: FECHA CAMBIO | Q2: ULTIMO | R2: PROXIMO | T2: FECHA CAMBIO | U2: ULTIMO | V2: PROXIMO | X2: FECHA CAMBIO | Y2: ULTIMO | Z2: PROXIMO | AC2: RAZON
A3: T-01 | B3: TRACTOR | C3: MASSEY FERGUSON | D3: 299 | G3: HR | H3: {=IF(A3:A1000="", "", IF(G3:G1000="KM", IFERROR(VLOOKUP(A3:A1000, DATA_LIMPIA!A:C, 3, FALSE), "Sin Datos"), IFERROR(VLOOKUP(A3:A1000, DATA_LIMPIA!A:C, 2, FALSE), "Sin Datos") ) )} -> 7649 | L3: 45643 | M3: 7350 | N3: =M3+350 -> 7700 | O3: =N3-H3 -> 51 | P3: 45301 | Q3: 7350 | R3: =Q3+600 -> 7950 | S3: =R3-H3 -> 301 | T3: 45301 | U3: 7350 | V3: =U3+1500 -> 8850 | W3: =V3-H3 -> 1201 | X3: 45392 | Y3: 7350 | Z3: =Y3+600 -> 7950 | AA3: =Z3-H3 -> 301
A4: T-02 | B4: TRACTOR | C4: SAME | D4: EXPLOREN95 | E4: HLZF62-8 | F4: JAIME HARCHA | G4: HR | H4: 7777 | L4: 45974 | M4: 7613 | N4: =M4+350 -> 7963 | O4: =N4-H4 -> 186 | P4: 45301 | Q4: 7246 | R4: =Q4+600 -> 7846 | S4: =R4-H4 -> 69 | T4: 45301 | U4: 6507 | V4: =U4+1500 -> 8007 | W4: =V4-H4 -> 230 | X4: 45301 | Y4: 7246 | Z4: =Y4+600 -> 7846 | AA4: =Z4-H4 -> 69
A5: T-03 | B5: TRACTOR | C5: MASSEY FERGUSON | D5: 4292 | E5: HKVR32 | F5: ASERRADERO LUIS FRITZSCHE | G5: HR | H5: 5779 | L5: 46079 | M5: 5773 | N5: =M5+350 -> 6123 | O5: =N5-H5 -> 344 | P5: 46079 | Q5: 5773 | R5: =Q5+600 -> 6373 | S5: =R5-H5 -> 594 | T5: 46079 | U5: 5773 | V5: =U5+1500 -> 7273 | W5: =V5-H5 -> 1494 | X5: 46079 | Y5: 5773 | Z5: =Y5+600 -> 6373 | AA5: =Z5-H5 -> 594
A6: T-04 | B6: TRACTOR | C6: CASE | D6: 125 | E6: SHRB11-1 | F6: ITAU | G6: HR | H6: 4545 | L6: 45978 | M6: 4279 | N6: =M6+350 -> 4629 | O6: =N6-H6 -> 84 | P6: 45622 | Q6: 2698 | R6: =Q6+600 -> 3298 | S6: =R6-H6 -> -1247 | T6: 45622 | U6: 2698 | V6: =U6+1000 -> 3698 | W6: =V6-H6 -> -847 | X6: 45622 | Y6: 2698 | Z6: =Y6+600 -> 3298 | AA6: =Z6-H6 -> -1247
A7: T-05 | B7: TRACTOR | C7: DONGFENG | D7: DF404 | G7: HR | H7: 1641 | L7: 45568 | M7: 1304 | N7: =M7+350 -> 1654 | O7: =N7-H7 -> 13 | R7: =Q7+600 -> 600 | S7: =R7-H7 -> -1041 | V7: =U7+1500 -> 1500 | W7: =V7-H7 -> -141 | Z7: =Y7+600 -> 600 | AA7: =Z7-H7 -> -1041
A8: T-06 | B8: TRACTOR | C8: CASE | D8: 155 | E8: VDYH39 | G8: HR | H8: 1195 | L8: 46009 | M8: 900 | N8: =M8+350 -> 1250 | O8: =N8-H8 -> 55 | P8: 45952 | Q8: 642 | R8: =Q8+600 -> 1242 | S8: =R8-H8 -> 47 | T8: 45952 | U8: 642 | V8: =U8+1500 -> 2142 | W8: =V8-H8 -> 947 | X8: 45955 | Y8: 642 | Z8: =Y8+600 -> 1242 | AA8: =Z8-H8 -> 47

Sheet motoniv
A1: 5 | L1: MOTOR | P1: TRANSMISION | T1: HIDRAULICO | X1: DIFERENCIAL
A2: COD | B2: MAQUINARIA | C2: MARCA | D2: MODELO | E2: PATENTE | F2: PROPIETARIO | G2: KM/HR | H2: ACTUAL | I2: Permiso de circulacion | J2: SOAP | K2: REV.TECNICA | L2: FECHA CAMBIO | M2: ULTIMO | N2: PROXIMO FILTROS | O2: FALTAN | P2: FECHA CAMBIO | Q2: ULTIMO | R2: PROXIMO FILTROS | T2: FECHA CAMBIO | U2: ULTIMO | V2: PROXIMO FILTROS | X2: FECHA CAMBIO | Y2: ULTIMO | Z2: PROXIMO FILTROS | AC2: RAZON
A3: MN-01 | B3: MOTONIVELADORA | C3: JOHN DEERE | D3: 0 | E3: YE3487 | F3: HARCHAMAQ | G3: HR | H3: {=IF(A3:A1000="", "", IF(G3:G1000="KM", IFERROR(VLOOKUP(A3:A1000, DATA_LIMPIA!A:C, 3, FALSE), "Sin Datos"), IFERROR(VLOOKUP(A3:A1000, DATA_LIMPIA!A:C, 2, FALSE), "Sin Datos") ) )} -> 15343 | I3: 45565 | J3: 45565 | K3: 46543 | L3: 45327 | M3: 15200 | N3: =M3+350 -> 15550 | O3: =N3-H3 -> 207 | Q3: =M3+0 -> 15200 | R3: =Q3+2000 -> 17200 | S3: =R3-H3 -> 1857 | U3: 14742 | V3: =U3+2000 -> 16742 | W3: =V3-H3 -> 1399 | Y3: 14742 | Z3: =Y3+1000 -> 15742 | AA3: =Z3-H3 -> 399 | AC3: nsoesnosenosne
A4: MN-02 | B4: MOTONIVELADORA | C4: KOMATSU | D4: GD675-3EO | E4: CKPV.95-2 | F4: HARCHAMAQ | G4: HR | H4: 13151 | I4: 46295 | J4: 46295 | K4: 47047 | L4: 46091 | M4: 13132 | N4: =M4+350 -> 13482 | O4: =N4-H4 -> 331 | P4: 45995 | Q4: 12729 | R4: =Q4+2000 -> 14729 | S4: =R4-H4 -> 1578 | T4: 45995 | U4: 12729 | V4: =U4+2000 -> 14729 | W4: =V4-H4 -> 1578 | X4: 45995 | Y4: 12729 | Z4: =Y4+1000 -> 13729 | AA4: =Z4-H4 -> 578
A5: MN-03 | B5: MOTONIVELADORA | C5: KOMATSU | D5: GD675-5 | E5: KTRL-62 | F5: KOMATSU | G5: HR | H5: 8299 | I5: 46295 | J5: 46295 | K5: 46259 | L5: 46074 | M5: 8207 | N5: =M5+350 -> 8557 | O5: =N5-H5 -> 258 | P5: 45997 | Q5: 7815 | R5: =Q5+2000 -> 9815 | S5: =R5-H5 -> 1516 | T5: 45997 | U5: 7815 | V5: =U5+2000 -> 9815 | W5: =V5-H5 -> 1516 | X5: 45997 | Y5: 7815 | Z5: =Y5+1000 -> 8815 | AA5: =Z5-H5 -> 516
A6: MN-04 | B6: MOTONIVELADORA | C6: VOLVO | D6: G730B | E6: YF5586 | F6: PAVIMENTOS QUILIN | G6: HR | H6: 12172 | I6: 46295 | J6: 46295 | K6: 47044 | L6: 45538 | M6: 11967 | N6: =M6+350 -> 12317 | O6: =N6-H6 -> 145 | P6: 45538 | Q6: 11967 | R6: =Q6+2000 -> 13967 | S6: =R6-H6 -> 1795 | T6: 45538 | U6: 11967 | V6: =U6+2000 -> 13967 | W6: =V6-H6 -> 1795 | X6: 45538 | Y6: 11967 | Z6: =Y6+1000 -> 12967 | AA6: =Z6-H6 -> 795

Sheet otro
A1: 8 | M1: MOTOR | Q1: HIDRÁULICO | U1: MANDO FINAL | Y1: DIFERENCIAL | AD1: TRANSMISIÓN | AH1: DIRECCION
A2: COD | B2: MAQUINARIA | C2: MARCA | D2: MODELO | E2: PATENTE | F2: PROPIETARIO | G2: KM/HR | H2: ACTUAL | I2: Permiso de circulacion | J2: SOAP | K2: REV.TECNICA | L2: LUGAR | M2: FECHA CAMBIO | N2: ULTIMO | O2: PRÓXIMO | P2: FALTAN | Q2: FECHA CAMBIO | R2: ULTIMO | S2: PRÓXIMO | U2: FECHA CAMBIO | V2: ULTIMO | W2: PROXIMO | Y2: FECHA CAMBIO | Z2: FECHA CAMBIO | AA2: ULTIMO | AB2: PROXIMO | AD2: FECHA CAMBIO | AE2: ULTIMO | AF2: PROXIMO | AH2: FECHA CAMBIO | AI2: ULTIMO | AJ2: PROXIMO | AM2: RAZON
A3: P-220 | B3: CHANCADOR PRIMARIO | G3: HR | H3: {=IF(A3:A1000="", "", IF(G3:G1000="KM", IFERROR(VLOOKUP(A3:A1000, DATA_LIMPIA!A:C, 3, FALSE), "Sin Datos"), IFERROR(VLOOKUP(A3:A1000, DATA_LIMPIA!A:C, 2, FALSE), "Sin Datos") ) )} -> Sin Datos | P3: {=IF(A3:A1000="", "", IF(G3:G1000="KM", IFERROR(VLOOKUP(A3:A1000, DATA_LIMPIA!A:C, 3, FALSE), "Sin Datos"), IFERROR(VLOOKUP(A3:A1000, DATA_LIMPIA!A:C, 2, FALSE), "Sin Datos") ) )} -> #REF!
B4: MOTOR PILOTERA | G4: HR | L4: DOP 46 | M4: 45139 | N4: 0 | O4: =N4+250 -> 250 | P4: =O4-H4 -> 250
A5: GM-01 | B5: GRUA MOVIL | C5: KOMATSU | D5: LW250-3 | E5: YZ9670-2 | F5: HARCHAMAQ | G5: HR | H5: 738 | L5: DOP 46 | M5: 45881 | N5: 489 | O5: =N5+350 -> 839 | P5: =O5-H5 -> 101 | AW5: 15
A6: GM-02 | B6: GRUA MOVIL | C6: TEREX | D6: HC-110 | G6: HR | H6: 22330 | L6: TALLER | M6: 45791 | N6: 22027 | O6: =N6+350 -> 22377 | P6: =O6-H6 -> 47 | Q6: 45791 | R6: 21605 | S6: =R6+2000 -> 23605 | T6: =S6-H6 -> 1275 | U6: 45791 | V6: 21605 | AD6: 45791 | AE6: 21605 | AH6: 45791 | AI6: 21605
A7: GM-03 | B7: GRUA MOVIL | C7: TEREX | D7: HC-110 | H7: 4864 | L7: TALLER | M7: 46065 | N7: 4824 | O7: =N7+350 -> 5174 | P7: =O7-H7 -> 310
A8: GM-04 | B8: GRUA MOVIL | C8: TEREX | D8: RT 345-1 XL | H8: 2929 | L8: TALLER | M8: 46088 | N8: 2901 | O8: =N8+350 -> 3251 | P8: =O8-H8 -> 322 | Q8: 45932 | R8: 2528 | S8: =R8+2000 -> 4528 | T8: =S8-H8 -> 1599 | Y8: 45932 | Z8: 2528 | AD8: 45932 | AE8: 2528
A9: P-01 | B9: PLANTA ARIDOS | C9: TESAP | D9: INPACTOR | G9: HR | H9: 1 | L9: TALLER SAN JOAQUIN | M9: 45351 | N9: 1657 | O9: =N9+350 -> 2007 | P9: =O9-H9 -> 2006
A10: P-02 | B10: PLANTA ARIDOS | C10: POWER | D10: SELECCIONADORA | E10: GENERADOR | G10: HR | H10: 8195 | L10: QUINCHILCA | M10: 45922 | N10: 8146 | O10: =N10+350 -> 8496 | P10: =O10-H10 -> 301
A11: P-03 | B11: PLANTA ARIDOS | C11: POWER SCREEN | D11: SYMMONS | H11: 1198 | L11: QUINCHILCA | M11: 45923 | N11: 1198 | O11: =N11+350 -> 1548 | P11: =O11-H11 -> 350
A12: P-04 | B12: PLANTA ARIDOS | C12: POWER SCREEN | D12: CRUSHER | E12: VLCD73 | H12: 3003 | L12: DV-10
A13: PH-01 | B13: PLANTA HORMIGON MOVIL | G13: HR | H13: Sin Datos | L13: USA GENERADOR | P13: =O13-H13 -> #VALUE!
A14: RC-01 | B14: RODILLO COMPACTADOR | C14: CATERPILLAR | D14: CS 533 E | E14: DBFS56 | F14: HARCHAMAQ | G14: HR | H14: 8531 | L14: DV-06 | M14: 46001 | N14: 8430 | O14: =N14+350 -> 8780 | P14: =O14-H14 -> 249 | Q14: 45530
A15: RC-02 | B15: RODILLO COMPACTADOR | C15: HAMM | E15: RSRK53 | F15: BCI | G15: HR | H15: 2092 | I15: 46295 | J15: 46295 | K15: 47070 | L15: DV-06 | M15: 45979 | N15: 1746 | O15: =N15+350 -> 2096 | P15: =O15-H15 -> 4
A16: RL-01 | B16: RODILLO COMPACTADOR | C16: AMMANN | D16: AV 70X | E16: VHRZ35 | G16: HR | H16: 2249 | L16: DV-06 | N16: 1947 | O16: =N16+350 -> 2297 | P16: =O16-H16 -> 48
A17: RN-01 | B17: RODILLO NEUMATICO | C17: AMMANN | D17: AP 240 | E17: VHRZ34 | G17: HR | H17: 6499 | L17: DV-06 | M17: 45852 | N17: 6262 | O17: =N17+350 -> 6612 | P17: =O17-H17 -> 113 | AD17: 45852 | AE17: 6262 | AF17: =AE17+2000 -> 8262 | AG17: =AF17-O17 -> 1650 | AH17: 45852 | AI17: 6262 | AJ17: =AI17+2000 -> 8262 | AK17: =AJ17-O17 -> 1650
A18: GV-01 | B18: GRAVILLADORA | C18: ETNYRE | D18: FWD | E18: VHRZ33 | G18: HR | H18: 413 | I18: NO NECESITA | J18: NO NECESITA | K18: NO NECESITA | L18: DV-06 | M18: 46091 | N18: 335 | O18: =N18+350 -> 685 | P18: =O18-H18 -> 272
A19: TE-01 | B19: TERMINADORA | C19: VOLVO | D19: TITAN | E19: YF5586 | F19: PAVIMENTOS QUILIN | G19: HR | H19: Sin Datos | L19: TALLER | P19: =O19-H19 -> #VALUE!
A20: VH-01 | B20: VIBRO HINCADORA | G20: HR | H20: 8529 | L20: TALLER | N20: 8529 | O20: =N20+350 -> 8879 | P20: =O20-H20 -> 350
A21: BA-01 | B21: BARREDORA | C21: LAYMOR | D21: SM450-ST | E21: RBGW23 | G21: HR | H21: 1408 | L21: DV-06 | M21: 45915 | N21: 1189 | O21: =N21+350 -> 1539 | P21: =O21-H21 -> 131
A22: SE-01 | B22: SELLADORA | C22: COLUMBIA | D22: CLYGZC350 | E22: PKLX48 | F22: HARCHAMAQ | G22: HR | H22: Sin Datos | N22: 0 | O22: 0 | P22: =O22-H22 -> #VALUE!
A23: BA-02 | B23: BARREDORA | C23: BROCE | E23: SWCX77 | H23: Sin Datos

Sheet GE
A1: 8 | H1: MOTOR
A2: COD. NUEVO | B2: EQUIPO | C2: MARCA | D2: PROPIETARIO | F2: KM/HR | G2: UBICACIÓN | H2: FECHA DE CAMBIO | I2: ULTIMA | J2: ACTUAL | K2: PROXIMA | L2: FALTAN | P2: RAZON
A3: G-01 | B3: GENERADOR | C3: JHON DEERE | E3: 150KVA | F3: HR | G3: DV010 | H3: 46094 | I3: 4312 | J3: {=IF(A3:A1000="", "", IF(F3:F1000="KM", IFERROR(VLOOKUP(A3:A1000, DATA_LIMPIA!A:C, 3, FALSE), 0), IFERROR(VLOOKUP(A3:A1000, DATA_LIMPIA!A:C, 2, FALSE), 0) ) )} -> 4347 | K3: =I3+350 -> 4662 | L3: =(K3-J3) -> 315
A4: G-02 | B4: GENERADOR | C4: KOLVOC | G4: COLLICO GALPÓNES
A5: G-03 | B5: GENERADOR | C5: CUMMINS | E5: 440KVA | F5: HR | G5: PLQ - PLANTA CHANCADO Quinchilca | H5: 46065 | I5: 18824 | J5: 19017 | K5: =I5+350 -> 19174 | L5: =(K5-J5) -> 157 | M5: Pedro Villacura | N5: Plataforma
A6: G-04 | B6: GENERADOR | C6: TOYAMA | E6: 33KVA | G6: BODEGA | H6: 46028 | J6: 0 | L6: =(K6-J6) -> 0
A7: G-05 | B7: GENERADOR | C7: KOLVOC | E7: 17KVA | G7: DOP48 | J7: 0 | L7: =(K7-J7) -> 0
A8: G-06 | B8: GENERADOR | C8: CATERPILLAR | E8: 60KVA | G8: BODEGA | H8: 46095 | I8: 20656 | J8: 20656
A9: G-07 | B9: GENERADOR | C9: PERKING | E9: 200KVA | F9: HR | G9: POZO SAN JOAQUIN | H9: 46046 | I9: 5422 | J9: 5707 | K9: =I9+350 -> 5772 | L9: =(K9-J9) -> 65 | M9: Moisés | O9: SE COBRA MANTENCION
A10: G-08 | B10: GENERADOR | C10: CUMMINS | E10: 330KVA | F10: HR | G10: DV010 | H10: 46066 | I10: 5592 | J10: 5755 | K10: =I10+350 -> 5942 | L10: =(K10-J10) -> 187 | M10: Camila Guajardo | N10: 9 31 97 76 86
A11: G-09 | B11: GENERADOR | C11: GH POWER | E11: 22KVA | G11: BODEGA | H11: 46048 | I11: 0 | J11: 0 | L11: =(K11-J11) -> 0
A12: G-10 | B12: GENERADOR | C12: CUMMINS | E12: 110KVA | F12: HR | G12: DOP 046 | H12: 45988 | I12: 6721 | J12: 6976 | K12: =I12+350 -> 7071 | L12: =(K12-J12) -> 95
A13: G-11 | B13: GENERADOR | C13: CUMMINS | E13: 330KVA | F13: HR | G13: DV08 | H13: 46002 | I13: 4923 | J13: 5086 | K13: =I13+350 -> 5273 | L13: =(K13-J13) -> 187 | M13: Juan Leiva | N13: 9 54 96 94 41

Sheet semirem
A1: 17
A2: 7 | B2: TIPO MAQUINARIA | C2: MARCA | D2: MODELO | E2: PATENTE | F2: PROPIETARIO | G2: PERMISO CIRCULACION | H2: SOAP | I2: REV.TECNICA
A3: B-01 | B3: BATEA | C3: RANDON | D3: SR BA AB 03 20 | E3: JB3026 | F3: HARCHA MAQUINARIA | G3: 46295 | H3: 46295 | I3: 46140 | J3: =TEXT(I3,"MMMM") -> abril
A4: B-02 | B4: BATEA | C4: RANDON | D4: SR BA AB 03 20 | E4: JB9039-2 | F4: HARCHA MAQUINARIA | G4: 46295 | H4: 46295 | I4: 46157 | J4: =TEXT(I4,"MMMM") -> mayo
A5: B-03 | B5: BATEA | C5: TREMACK | D5: SRTTT203N | E5: JB1879 | F5: MAQUINARIAS PEÑALOLEN | G5: 46295 | H5: 46295 | I5: 46271 | J5: =TEXT(I5,"MMMM") -> septiembre
